<?xml version="1.0" ?>

<robot name="arm" xmlns:xacro="http://www.ros.org/wiki/xacro">

<!-- 색깔지정 -->
    <material name="black">
        <color rgba="0.0 0.0 0.0 1.0"/>
    </material>
    <material name="orange">
        <color rgba="1.0 0.423529411765 0.0392156862745 1.0"/>
    </material>

<!-- link 시작 -->
<!-- 어깨 -->
    <link name="base"/>

    <joint name="fixed" type="fixed">
        <parent link="base"/>
        <child link="link1"/>
    </joint>

    <link name="link1">
        <collision>
            <origin rpy="0 0 0" xyz="0.005 -0.195 0.948"/>
            <geometry>
                <box size="0.18 0.25 0.23"/>
            </geometry>
        </collision>
        <visual>
            <origin rpy="0 0 0" xyz="0.005 -0.195 0.948"/>
            <geometry>
            <mesh filename="package://arm_description/meshes/s11.stl" scale="0.001 0.001 0.001"/>
            <!--    <box size="0.04 0.04 0.63"/>-->
            </geometry>
            <!--<material name="black"/>-->
        </visual>
        <inertial>
            <mass value="1"/>
            <inertia ixx="1.0" ixy="0.0" ixz="0.0" iyy="1.0" iyz="0.0" izz="1.0"/>
        </inertial>
    </link>

    <joint name="joint1" type="revolute">
        <parent link="link1"/>
        <child link="link2"/>
        <origin rpy="0 0 0" xyz="0 0 1"/>
        <axis xyz="0 1 0"/>
        <limit effort="30" lower="-3.14" upper="3.14" velocity="1.571"/>
    </joint>

    <link name="link2">
        <collision>
            <origin rpy="0 0 0" xyz="0 0 0"/>
            <geometry>
            <box size="0.08 0.12 0.10"/>
            <mesh filename="package://arm_description/meshes/s2.stl" scale="0.001 0.001 0.001"/>
            </geometry>
        </collision>
        <visual>
            <origin rpy="0 0 0" xyz="0 0 0"/>
            <geometry>
            <mesh filename="package://arm_description/meshes/s2.stl" scale="0.001 0.001 0.001"/>
            </geometry>
        <!--<material name="black"/>-->

        </visual>
        <inertial>
            <mass value="1"/>
            <inertia ixx="1.0" ixy="0.0" ixz="0.0" iyy="1.0" iyz="0.0" izz="1.0"/>
        </inertial>
    </link>

    <joint name="joint2" type="revolute">
        <parent link="link2"/>
        <child link="link3"/>
        <origin rpy="0 0 0" xyz="0 0 0"/>
        <axis xyz="1 0 0"/>
        <limit effort="30" lower="-0.5" upper="3.14" velocity="1.571"/>
    </joint>

    <link name="link3">
        <collision>
            <origin rpy="0 0 0" xyz="0 0 0"/>
            <geometry>
                <mesh filename="package://arm_description/meshes/s3.stl" scale="0.001 0.001 0.001"/>
                <box size="0.07 0.12 0.24"/>
            </geometry>
        </collision>
        <visual>
            <origin rpy="0 0 0" xyz="0 0 0"/>
            <geometry>
            <mesh filename="package://arm_description/meshes/s3.stl" scale="0.001 0.001 0.001"/>
            </geometry>
        <!--<material name="black"/>-->
        </visual>
        <inertial>
            <origin rpy="0 0 0" xyz="0 0 0"/>
            <mass value="1"/>
            <inertia ixx="1.0" ixy="0.0" ixz="0.0" iyy="1.0" iyz="0.0" izz="1.0"/>
        </inertial>
    </link> 
    
    <joint name="joint3" type="revolute">
        <parent link="link3"/>
        <child link="link4"/>
        <origin rpy="0 0 0" xyz="0 0 0"/>
        <axis xyz="0 0 1"/>
        <limit effort="30" lower="-3.14" upper="3.14" velocity="1.571"/>
    </joint>

    <link name="link4">
        <collision>
            <origin rpy="0 0 0" xyz="0 0 -0.252"/>
            <geometry>
                <mesh filename="package://arm_description/meshes/s4.stl" scale="0.001 0.001 0.001"/>
                <box size="0.085 0.065 0.08"/>
            </geometry>
        </collision>
        <visual>
            <origin rpy="0 0 0" xyz="0 0 -0.252"/>
            <geometry>
                <mesh filename="package://arm_description/meshes/s4.stl" scale="0.001 0.001 0.001"/>
            </geometry>
        </visual>
        <inertial>
            <origin rpy="0 0 0" xyz="0 0 -0.252"/>
            <mass value="1"/>
            <inertia ixx="1.0" ixy="0.0" ixz="0.0" iyy="1.0" iyz="0.0" izz="1.0"/>
        </inertial>
    </link> 
<!-- 팔꿈치 -->
    <joint name="joint4" type="revolute">
        <parent link="link4"/>
        <child link="link5"/>
        <origin rpy="0 0 0" xyz="0.015 0 -0.265"/>
        <axis xyz="0 1 0"/>
        <limit effort="30" lower="-0.35" upper="2.0" velocity="1.571"/>
    </joint>

    <link name="link5">
        <collision>
            <origin rpy="0 0 0" xyz="0 0 0"/>
            <geometry>
                <mesh filename="package://arm_description/meshes/s5_1.stl" scale="0.001 0.001 0.001"/>
                <box size="0.11 0.04 0.19"/>
            </geometry>
        </collision>
        <visual>
            <origin rpy="0 0 0" xyz="0 0 0"/>
            <geometry>
                <mesh filename="package://arm_description/meshes/s5_1.stl" scale="0.001 0.001 0.001"/>
            </geometry>
        </visual>
        <inertial>
            <origin rpy="0 0 0" xyz="0 0 0"/>
            <mass value="1"/>
            <inertia ixx="1.0" ixy="0.0" ixz="0.0" iyy="1.0" iyz="0.0" izz="1.0"/>
        </inertial>
    </link> 

<!-- 손목  수정필요-->

<joint name="joint5" type="revolute">
        <parent link="link5"/>
        <child link="link6"/>
        <origin rpy="0 0 0" xyz="0 0 0"/>
        <axis xyz="1 0 0"/>
        <limit effort="30" lower="-3.14" upper="3.14" velocity="1.571"/>
    </joint>

    <link name="link6">
        <collision>
            <origin rpy="0 0 0" xyz="0.15 0.007 0.0"/>
            <geometry>
                <mesh filename="package://arm_description/meshes/s6_1.stl" scale="0.001 0.001 0.001"/>
                <box size="0.05 0.05 0.13"/>
            </geometry>
        </collision>
        <visual>
            <origin rpy="0 0 0" xyz="0.15 0.007 0.0"/>
            <geometry>
                <mesh filename="package://arm_description/meshes/s6_1.stl" scale="0.001 0.001 0.001"/>
            </geometry>
        </visual>
        <inertial>
            <origin rpy="0 0 0" xyz="-0.005 0.007 -0.17"/>
            <mass value="1"/>
            <inertia ixx="1.0" ixy="0.0" ixz="0.0" iyy="1.0" iyz="0.0" izz="1.0"/>
        </inertial>
    </link> 

    <joint name="joint6" type="revolute">
        <parent link="link6"/>
        <child link="link7"/>
        <origin rpy="0 0 0" xyz="0.205 0.015 0.005"/>
        <axis xyz="0 1 0"/>
        <limit effort="30" lower="-1.8" upper="1.8" velocity="1.571"/>
    </joint>

    <link name="link7">
        <collision>
            <origin rpy="0 0 0" xyz="0 0 0"/>
            <geometry>
                <mesh filename="package://arm_description/meshes/s7_1.stl" scale="0.001 0.001 0.001"/>
                <box size="0.07 0.02 0.1"/>
            </geometry>
        </collision>
        <visual>
            <origin rpy="0 0 0" xyz="0 0 0"/>
            <geometry>
                <mesh filename="package://arm_description/meshes/s7_1.stl" scale="0.001 0.001 0.001"/>
            </geometry>
            <material name="black"/>
        </visual>
        <inertial>
            <origin rpy="0 0 0" xyz="0 0 0"/>
            <mass value="1"/>
            <inertia ixx="1.0" ixy="0.0" ixz="0.0" iyy="1.0" iyz="0.0" izz="1.0"/>
        </inertial>
    </link> 

</robot>